Workbook

Sheet Read me
A1: JARVUS 2 - STRATEGIES (version 5)
A2: What this is: ONLY the strategy library. Markets: US stocks, crypto and meme coins (no ETFs, forex, futures or options). The bots are in JARVUS_3_BOTS.xlsx and the boss prompt is JARVUS_1_MASTER_PROMPT.md.
A3: How to read the grades:
A4: - Catalog grade = what the original list said (A peer-reviewed, B working paper, C book/industry, D trader idea).
A5: - Jarvus grade = my rating for THIS exact use (this bar size, this market, after costs). NOTHING here has proof of profit after costs, so no strategy is above B.
A6: - Check the Caveat column: several ideas are daily-bar ideas stretched to hourly bars, and the opening-range idea lost its edge after costs in an outside replication.
A7: What was cleaned:
A8: - KEPT: ideas that run on the data we have, trade US stocks or crypto, have a hard stop, and can finish inside the day.
A9: - DROPPED: all "flip" exits (206 variants), because they have no hard stop.
A10: - CUT: ideas that need missing data, forex/futures-only ideas, overnight/daily ideas, and weak copies of stronger ideas.
A11: - TRIMMED: Tier 2 tries only 2 filters per idea. Every extra variant tried makes the Deflated Sharpe check harder. Rule of thumb from the research: about 45 trials is the most you should try on 5 years of daily data, and fewer on less data.
A12: - ADDED: 4 VWAP variants (research cards ST023, ST024). NOT built yet.
... A26: - Sheet Measured (BTC) holds the numbers. They are BTC-only, hourly, 2019-2026. They do NOT prove anything for stocks or for other coins.

Sheet Summary
A1: Summary
A3: Kept variants - Tier 1 CORE | B3: =COUNTIF(Keep!A:A,"1 CORE") -> 48
A4: Kept variants - Tier 2 TEST | B4: =COUNTIF(Keep!A:A,"2 TEST") -> 52
A5: Kept variants - total | B5: =B3+B4 -> 100
A6: Starter variants (assigned to bots now) | B6: =COUNTIF(Keep!B:B,"Yes") -> 16
A7: New strategies to build | B7: =COUNTA('New (to build)'!A:A)-1 -> 11
A8: Ideas cut (base ideas) | B8: =COUNTA(Cut!A:A)-1 -> 56
A9: Cut - needs missing data | B9: =COUNTIF(Cut!E:E,"*needs data*") -> 15
A10: Cut - forex/futures only | B10: =COUNTIF(Cut!E:E,"*forex*") -> 4
A11: Cut - overnight/daily | B11: =COUNTIF(Cut!E:E,"*overnight*") -> 3
A12: Cut - weak copies (grade D) | B12: =COUNTIF(Cut!E:E,"*copy of*") -> 32
A13: Cut - needs a 2nd market feed | B13: =B8-SUM(B9:B12) -> 2
A14: Variants graded A by Jarvus | B14: =COUNTIF(Keep!E:E,"A") -> 0
A15: Variants graded B by Jarvus | B15: =COUNTIF(Keep!E:E,"B") -> 4
A16: Variants graded C by Jarvus | B16: =COUNTIF(Keep!E:E,"C") -> 45
A17: Variants graded D by Jarvus | B17: =COUNTIF(Keep!E:E,"D") -> 51
A19: Ideas on the 'Do not build' list | B19: =COUNTA('Do not build'!A:A)-1 -> 12
A20: Counts are live formulas on the other sheets.

Sheet Keep
A1: Tier | B1: Starter | C1: ID | D1: Job | E1: Jarvus grade | F1: Catalog grade | G1: Evidence applies to | H1: Caveat | I1: Risk | J1: Bars | K1: Markets | L1: Entry | M1: Exit | N1: Stop | O1: Settings | P1: v5 crypto override | Q1: Your BTC test (2019-2026)
A2: 1 CORE | B2: Yes | C2: active_orb.relvol.atr_bracket | D2: Stocks: opening-range breakout, only on busy days | E2: C | F2: B | G2: Single stocks "in play" ranked by relative volume, 5-min bars (Zarattini, Barbon, Aziz) | H2: Our version is a one-stock adaptation, not the paper's ranked universe. A replication on 5 index CFDs matched the gross result but net of costs it was about zero (costs were 6-12% of risk). | I2: medium (hard stop) | J2: 5m, 15m | K2: stock, etf | L2: active_orb signal turns non-zero and the 'relvol' filter allows it; orders go in at the NEXT bar's open (never the signal bar's close) | M2: stop 2 ATR, target 2R (4 ATR), whichever comes first; signal flip also exits | N2: stop at 2 ATR from entry | O2: bars=2, rv=1.5, n=14, stop_atr=2.0, target_r=2.0 | P2: Stocks only: no change (stop 2 ATR). | Q2: n/a (stocks)
A3: 1 CORE | B3: Yes | C3: active_orb.relvol.time | D3: Stocks: opening-range breakout, only on busy days | E3: C | F3: B | G3: Single stocks "in play" ranked by relative volume, 5-min bars (Zarattini, Barbon, Aziz) | H3: Our version is a one-stock adaptation, not the paper's ranked universe. A replication on 5 index CFDs matched the gross result but net of costs it was about zero (costs were 6-12% of risk). | I3: medium (hard stop) | J3: 5m, 15m | K3: stock, etf | L3: active_orb signal turns non-zero and the 'relvol' filter allows it; orders go in at the NEXT bar's open (never the signal bar's close) | M3: exit after 20 bars, or on a 2-ATR stop | N3: stop at 2 ATR from entry | O3: bars=2, rv=1.5, n=14, max_bars=20, stop_atr=2.0 | P3: Stocks only: no change (stop 2 ATR). | Q3: n/a (stocks)
A4: 1 CORE | B4: Yes | C4: connors_rsi_rev.vol_band.time | D4: Buy extreme short dips (3-part score) | E4: C | F4: C | G4: Daily bars (Connors Research, industry) | H4: Same as rsi2: daily-bar idea, hourly use unproven. | I4: medium (hard stop) | J4: 5m, 15m, 30m, 1h, 4h, 1d | K4: crypto, stock, etf, fx, future | L4: connors_rsi_rev signal turns non-zero and the 'vol_band' filter allows it; orders go in at the NEXT bar's open (never the signal bar's close) | M4: exit after 20 bars, or on a 2-ATR stop | N4: stop at 2 ATR from entry | O4: lo=10, max_bars=20, stop_atr=2.0 | P4: Crypto: stop 3-4 ATR (not 2), 0.6x size when volatility is LOUD, skip when QUIET, no Sat/Sun entries, skip if cost > 20% of 1R (20-33% = half size). | Q4: Not tested in your BTC study.
A5: 1 CORE | B5: Yes | C5: donchian_trend.adx.trail | D5: Ride a break of the recent high with a trailing stop | E5: C | F5: C | G5: Futures, daily bars (Turtle rules) | H5: Multi-day trend following. Intraday use is unproven. Best fit here is crypto. | I5: medium (hard stop) | J5: 5m, 15m, 30m, 1h, 4h, 1d | K5: crypto, stock, etf, fx, future | L5: donchian_trend signal turns non-zero and the 'adx' filter allows it; orders go in at the NEXT bar's open (never the signal bar's close) | M5: 3-ATR trailing stop; signal flip also exits | N5: 3-ATR trailing stop | O5: entry=55, exit=20, trail_atr=3.0 | P5: Crypto: stop 3-4 ATR (not 2), 0.6x size when volatility is LOUD, skip when QUIET, no Sat/Sun entries, skip if cost > 20% of 1R (20-33% = half size). | Q5: Not tested in your BTC study.
A6: 1 CORE | B6: Yes | C6: first_hour_momentum.session.time | D6: Stocks: first-30-min move predicts the last 30 min | E6: B | F6: A | G6: SPY (index ETF), 30-min bars, 1999-2012 (Gao, Han, Li, Zhou, JFE) | H6: Effect is real but small (about 2% of the variance). Stronger on volatile days. Weaker on QQQ. Reviews say costs likely wipe it out for most traders. Our single-stock use is an extension. | I6: medium (hard stop) | J6: 5m, 15m | K6: stock, etf | L6: first_hour_momentum signal turns non-zero and the 'session' filter allows it; orders go in at the NEXT bar's open (never the signal bar's close) | M6: exit after 20 bars, or on a 2-ATR stop | N6: stop at 2 ATR from entry | O6: max_bars=20, stop_atr=2.0 | P6: Stocks only: no change (stop 2 ATR). | Q6: n/a (stocks)
A7: 1 CORE | B7: Yes | C7: ibs_reversion.trend200.time | D7: Buy weak closes (price near bar low) that bounce back | E7: C | F7: B | G7: ETFs, daily bars (Pagonidis 2013 working paper) | H7: Evidence is for daily bars held a few days. Hourly bars with a same-day exit is an unproven extension. | I7: medium (hard stop) | J7: 5m, 15m, 30m, 1h, 4h, 1d | K7: crypto, stock, etf, fx, future | L7: ibs_reversion signal turns non-zero and the 'trend200' filter allows it; orders go in at the NEXT bar's open (never the signal bar's close) | M7: exit after 20 bars, or on a 2-ATR stop | N7: stop at 2 ATR from entry | O7: lo=0.2, max_bars=20, stop_atr=2.0 | P7: Crypto: stop 3-4 ATR (not 2), 0.6x size when volatility is LOUD, skip when QUIET, no Sat/Sun entries, skip if cost > 20% of 1R (20-33% = half size). | Q7: Not tested in your BTC study.
A8: 1 CORE | B8: Yes | C8: noise_band_momentum.none.time | D8: Stocks/ETFs: trade when price leaves its normal daily range | E8: C | F8: B | G8: SPY intraday (Zarattini, Aziz, Barbon, author tutorial) | H8: Our version is an adaptation, not the authors' method. | I8: medium (hard stop) | J8: 15m, 30m | K8: stock, etf | L8: noise_band_momentum signal turns non-zero and the 'none' filter allows it; orders go in at the NEXT bar's open (never the signal bar's close) | M8: exit after 20 bars, or on a 2-ATR stop | N8: stop at 2 ATR from entry | O8: n=14, m=1.0, max_bars=20, stop_atr=2.0 | P8: Stocks only: no change (stop 2 ATR). | Q8: n/a (stocks)
A9: 1 CORE | B9: Yes | C9: nr7_breakout.adx.atr_bracket | D9: Quiet bar (narrowest of 7) then breakout | E9: C | F9: C | G9: Futures, daily bars (Crabel book) | H9: Daily-bar idea. Intraday use is unproven. | I9: medium (hard stop) | J9: 5m, 15m, 30m, 1h, 4h, 1d | K9: crypto, stock, etf, fx, future | L9: nr7_breakout signal turns non-zero and the 'adx' filter allows it; orders go in at the NEXT bar's open (never the signal bar's close) | M9: stop 2 ATR, target 2R (4 ATR), whichever comes first; signal flip also exits | N9: stop at 2 ATR from entry | O9: n=7, stop_atr=2.0, target_r=2.0 | P9: Crypto: stop 3-4 ATR (not 2), 0.6x size when volatility is LOUD, skip when QUIET, no Sat/Sun entries, skip if cost > 20% of 1R (20-33% = half size). | Q9: Not tested in your BTC study.
A10: 1 CORE | B10: Yes | C10: nr7_breakout.relvol.atr_bracket | D10: Quiet bar (narrowest of 7) then breakout | E10: C | F10: C | G10: Futures, daily bars (Crabel book) | H10: Daily-bar idea. Intraday use is unproven. | I10: medium (hard stop) | J10: 5m, 15m, 30m, 1h, 4h, 1d | K10: crypto, stock, etf, fx, future | L10: nr7_breakout signal turns non-zero and the 'relvol' filter allows it; orders go in at the NEXT bar's open (never the signal bar's close) | M10: stop 2 ATR, target 2R (4 ATR), whichever comes first; signal flip also exits | N10: stop at 2 ATR from entry | O10: n=7, stop_atr=2.0, target_r=2.0 | P10: Crypto: stop 3-4 ATR (not 2), 0.6x size when volatility is LOUD, skip when QUIET, no Sat/Sun entries, skip if cost > 20% of 1R (20-33% = half size). | Q10: Not tested in your BTC study.
A11: 1 CORE | B11: Yes | C11: orb.relvol.atr_bracket | D11: Stocks: classic opening-range breakout | E11: C | F11: C | G11: Futures and stocks, 5-min bars (Crabel 1990; Zarattini & Aziz 2023 working paper) | H11: Replication on index CFDs: gross reproduced, net about zero after spread and slippage. Costs decide this one. | I11: medium (hard stop) | J11: 5m, 15m | K11: stock, etf, future, fx | L11: orb signal turns non-zero and the 'relvol' filter allows it; orders go in at the NEXT bar's open (never the signal bar's close) | M11: stop 2 ATR, target 2R (4 ATR), whichever comes first; signal flip also exits | N11: stop at 2 ATR from entry | O11: bars=3, stop_atr=2.0, target_r=2.0 | P11: Stocks only: no change (stop 2 ATR). | Q11: n/a (stocks)
A12: 1 CORE | B12: Yes | C12: rsi2_reversion.trend200.time | D12: Buy sharp short dips inside an uptrend | E12: C | F12: C | G12: US stocks/ETFs, daily bars (Connors & Alvarez book) | H12: Book results on daily bars. Hourly + same-day exit is unproven. No solid source found on how well it works today. | I12: medium (hard stop) | J12: 5m, 15m, 30m, 1h, 4h, 1d | K12: crypto, stock, etf, fx, future | L12: rsi2_reversion signal turns non-zero and the 'trend200' filter allows it; orders go in at the NEXT bar's open (never the signal bar's close) | M12: exit after 20 bars, or on a 2-ATR stop | N12: stop at 2 ATR from entry | O12: lo=10, exit=70, max_bars=20, stop_atr=2.0 | P12: Crypto: stop 3-4 ATR (not 2), 0.6x size when volatility is LOUD, skip when QUIET, no Sat/Sun entries, skip if cost > 20% of 1R (20-33% = half size). | Q12: RSI-2 on BTC hourly: 1 ATR stop / 24h = +0.076R before costs, -0.406R after 30bp. 4 ATR stop / 96h = +0.113R before costs, -0.003R after. A real but tiny edge that fees eat. Compare with 'take every bar' (+0.085R / -0.026R).
A13: 1 CORE | B13: Yes | C13: vol_breakout.adx.atr_bracket | D13: Breakout when volatility expands | E13: C | F13: C | G13: Futures, daily bars (Larry Williams, industry) | H13: Daily-bar idea. Intraday use is unproven. Old bots using it averaged test Sharpe -4.2 (tiny samples). | I13: medium (hard stop) | J13: 5m, 15m, 30m, 1h, 4h, 1d | K13: crypto, stock, etf, fx, future | L13: vol_breakout signal turns non-zero and the 'adx' filter allows it; orders go in at the NEXT bar's open (never the signal bar's close) | M13: stop 2 ATR, target 2R (4 ATR), whichever comes first; signal flip also exits | N13: stop at 2 ATR from entry | O13: k=0.6, stop_atr=2.0, target_r=2.0 | P13: Crypto: stop 3-4 ATR (not 2), 0.6x size when volatility is LOUD, skip when QUIET, no Sat/Sun entries, skip if cost > 20% of 1R (20-33% = half size). | Q13: Not tested in your BTC study.
A14: 1 CORE | C14: active_orb.adx.atr_bracket | D14: Stocks: opening-range breakout, only on busy days | E14: C | F14: B | G14: Single stocks "in play" ranked by relative volume, 5-min bars (Zarattini, Barbon, Aziz) | H14: Our version is a one-stock adaptation, not the paper's ranked universe. A replication on 5 index CFDs matched the gross result but net of costs it was about zero (costs were 6-12% of risk). | I14: medium (hard stop) | J14: 5m, 15m | K14: stock, etf | L14: active_orb signal turns non-zero and the 'adx' filter allows it; orders go in at the NEXT bar's open (never the signal bar's close) | M14: stop 2 ATR, target 2R (4 ATR), whichever comes first; signal flip also exits | N14: stop at 2 ATR from entry | O14: bars=2, rv=1.5, n=14, stop_atr=2.0, target_r=2.0 | P14: Stocks only: no change (stop 2 ATR). | Q14: n/a (stocks)
A15: 1 CORE | C15: active_orb.adx.time | D15: Stocks: opening-range breakout, only on busy days | E15: C | F15: B | G15: Single stocks "in play" ranked by relative volume, 5-min bars (Zarattini, Barbon, Aziz) | H15: Our version is a one-stock adaptation, not the paper's ranked universe. A replication on 5 index CFDs matched the gross result but net of costs it was about zero (costs were 6-12% of risk). | I15: medium (hard stop) | J15: 5m, 15m | K15: stock, etf | L15: active_orb signal turns non-zero and the 'adx' filter allows it; orders go in at the NEXT bar's open (never the signal bar's close) | M15: exit after 20 bars, or on a 2-ATR stop | N15: stop at 2 ATR from entry | O15: bars=2, rv=1.5, n=14, max_bars=20, stop_atr=2.0 | P15: Stocks only: no change (stop 2 ATR). | Q15: n/a (stocks)
A16: 1 CORE | C16: active_orb.none.atr_bracket | D16: Stocks: opening-range breakout, only on busy days | E16: C | F16: B | G16: Single stocks "in play" ranked by relative volume, 5-min bars (Zarattini, Barbon, Aziz) | H16: Our version is a one-stock adaptation, not the paper's ranked universe. A replication on 5 index CFDs matched the gross result but net of costs it was about zero (costs were 6-12% of risk). | I16: medium (hard stop) | J16: 5m, 15m | K16: stock, etf | L16: active_orb signal turns non-zero and the 'none' filter allows it; orders go in at the NEXT bar's open (never the signal bar's close) | M16: stop 2 ATR, target 2R (4 ATR), whichever comes first; signal flip also exits | N16: stop at 2 ATR from entry | O16: bars=2, rv=1.5, n=14, stop_atr=2.0, target_r=2.0 | P16: Stocks only: no change (stop 2 ATR). | Q16: n/a (stocks)
A17: 1 CORE | C17: active_orb.none.time | D17: Stocks: opening-range breakout, only on busy days | E17: C | F17: B | G17: Single stocks "in play" ranked by relative volume, 5-min bars (Zarattini, Barbon, Aziz) | H17: Our version is a one-stock adaptation, not the paper's ranked universe. A replication on 5 index CFDs matched the gross result but net of costs it was about zero (costs were 6-12% of risk). | I17: medium (hard stop) | J17: 5m, 15m | K17: stock, etf | L17: active_orb signal turns non-zero and the 'none' filter allows it; orders go in at the NEXT bar's open (never the signal bar's close) | M17: exit after 20 bars, or on a 2-ATR stop | N17: stop at 2 ATR from entry | O17: bars=2, rv=1.5, n=14, max_bars=20, stop_atr=2.0 | P17: Stocks only: no change (stop 2 ATR). | Q17: n/a (stocks)
A18: 1 CORE | C18: connors_rsi_rev.none.atr_bracket | D18: Buy extreme short dips (3-part score) | E18: C | F18: C | G18: Daily bars (Connors Research, industry) | H18: Same as rsi2: daily-bar idea, hourly use unproven. | I18: medium (hard stop) | J18: 5m, 15m, 30m, 1h, 4h, 1d | K18: crypto, stock, etf, fx, future | L18: connors_rsi_rev signal turns non-zero and the 'none' filter allows it; orders go in at the NEXT bar's open (never the signal bar's close) | M18: stop 2 ATR, target 2R (4 ATR), whichever comes first; signal flip also exits | N18: stop at 2 ATR from entry | O18: lo=10, stop_atr=2.0, target_r=2.0 | P18: Crypto: stop 3-4 ATR (not 2), 0.6x size when volatility is LOUD, skip when QUIET, no Sat/Sun entries, skip if cost > 20% of 1R (20-33% = half size). | Q18: Not tested in your BTC study.
A19: 1 CORE | C19: connors_rsi_rev.none.time | D19: Buy extreme short dips (3-part score) | E19: C | F19: C | G19: Daily bars (Connors Research, industry) | H19: Same as rsi2: daily-bar idea, hourly use unproven. | I19: medium (hard stop) | J19: 5m, 15m, 30m, 1h, 4h, 1d | K19: crypto, stock, etf, fx, future | L19: connors_rsi_rev signal turns non-zero and the 'none' filter allows it; orders go in at the NEXT bar's open (never the signal bar's close) | M19: exit after 20 bars, or on a 2-ATR stop | N19: stop at 2 ATR from entry | O19: lo=10, max_bars=20, stop_atr=2.0 | P19: Crypto: stop 3-4 ATR (not 2), 0.6x size when volatility is LOUD, skip when QUIET, no Sat/Sun entries, skip if cost > 20% of 1R (20-33% = half size). | Q19: Not tested in your BTC study.
A20: 1 CORE | C20: connors_rsi_rev.trend200.atr_bracket | D20: Buy extreme short dips (3-part score) | E20: C | F20: C | G20: Daily bars (Connors Research, industry) | H20: Same as rsi2: daily-bar idea, hourly use unproven. | I20: medium (hard stop) | J20: 5m, 15m, 30m, 1h, 4h, 1d | K20: crypto, stock, etf, fx, future | L20: connors_rsi_rev signal turns non-zero and the 'trend200' filter allows it; orders go in at the NEXT bar's open (never the signal bar's close) | M20: stop 2 ATR, target 2R (4 ATR), whichever comes first; signal flip also exits | N20: stop at 2 ATR from entry | O20: lo=10, stop_atr=2.0, target_r=2.0 | P20: Crypto: stop 3-4 ATR (not 2), 0.6x size when volatility is LOUD, skip when QUIET, no Sat/Sun entries, skip if cost > 20% of 1R (20-33% = half size). | Q20: Not tested in your BTC study.
A21: 1 CORE | C21: connors_rsi_rev.trend200.time | D21: Buy extreme short dips (3-part score) | E21: C | F21: C | G21: Daily bars (Connors Research, industry) | H21: Same as rsi2: daily-bar idea, hourly use unproven. | I21: medium (hard stop) | J21: 5m, 15m, 30m, 1h, 4h, 1d | K21: crypto, stock, etf, fx, future | L21: connors_rsi_rev signal turns non-zero and the 'trend200' filter allows it; orders go in at the NEXT bar's open (never the signal bar's close) | M21: exit after 20 bars, or on a 2-ATR stop | N21: stop at 2 ATR from entry | O21: lo=10, max_bars=20, stop_atr=2.0 | P21: Crypto: stop 3-4 ATR (not 2), 0.6x size when volatility is LOUD, skip when QUIET, no Sat/Sun entries, skip if cost > 20% of 1R (20-33% = half size). | Q21: Not tested in your BTC study.
A22: 1 CORE | C22: connors_rsi_rev.vol_band.atr_bracket | D22: Buy extreme short dips (3-part score) | E22: C | F22: C | G22: Daily bars (Connors Research, industry) | H22: Same as rsi2: daily-bar idea, hourly use unproven. | I22: medium (hard stop) | J22: 5m, 15m, 30m, 1h, 4h, 1d | K22: crypto, stock, etf, fx, future | L22: connors_rsi_rev signal turns non-zero and the 'vol_band' filter allows it; orders go in at the NEXT bar's open (never the signal bar's close) | M22: stop 2 ATR, target 2R (4 ATR), whichever comes first; signal flip also exits | N22: stop at 2 ATR from entry | O22: lo=10, stop_atr=2.0, target_r=2.0 | P22: Crypto: stop 3-4 ATR (not 2), 0.6x size when volatility is LOUD, skip when QUIET, no Sat/Sun entries, skip if cost > 20% of 1R (20-33% = half size). | Q22: Not tested in your BTC study.
A23: 1 CORE | C23: donchian_trend.none.trail | D23: Ride a break of the recent high with a trailing stop | E23: C | F23: C | G23: Futures, daily bars (Turtle rules) | H23: Multi-day trend following. Intraday use is unproven. Best fit here is crypto. | I23: medium (hard stop) | J23: 5m, 15m, 30m, 1h, 4h, 1d | K23: crypto, stock, etf, fx, future | L23: donchian_trend signal turns non-zero and the 'none' filter allows it; orders go in at the NEXT bar's open (never the signal bar's close) | M23: 3-ATR trailing stop; signal flip also exits | N23: 3-ATR trailing stop | O23: entry=55, exit=20, trail_atr=3.0 | P23: Crypto: stop 3-4 ATR (not 2), 0.6x size when volatility is LOUD, skip when QUIET, no Sat/Sun entries, skip if cost > 20% of 1R (20-33% = half size). | Q23: Not tested in your BTC study.
A24: 1 CORE | C24: donchian_trend.trend200.trail | D24: Ride a break of the recent high with a trailing stop | E24: C | F24: C | G24: Futures, daily bars (Turtle rules) | H24: Multi-day trend following. Intraday use is unproven. Best fit here is crypto. | I24: medium (hard stop) | J24: 5m, 15m, 30m, 1h, 4h, 1d | K24: crypto, stock, etf, fx, future | L24: donchian_trend signal turns non-zero and the 'trend200' filter allows it; orders go in at the NEXT bar's open (never the signal bar's close) | M24: 3-ATR trailing stop; signal flip also exits | N24: 3-ATR trailing stop | O24: entry=55, exit=20, trail_atr=3.0 | P24: Crypto: stop 3-4 ATR (not 2), 0.6x size when volatility is LOUD, skip when QUIET, no Sat/Sun entries, skip if cost > 20% of 1R (20-33% = half size). | Q24: Not tested in your BTC study.
A25: 1 CORE | C25: first_hour_momentum.adx.time | D25: Stocks: first-30-min move predicts the last 30 min | E25: B | F25: A | G25: SPY (index ETF), 30-min bars, 1999-2012 (Gao, Han, Li, Zhou, JFE) | H25: Effect is real but small (about 2% of the variance). Stronger on volatile days. Weaker on QQQ. Reviews say costs likely wipe it out for most traders. Our single-stock use is an extension. | I25: medium (hard stop) | J25: 5m, 15m | K25: stock, etf | L25: first_hour_momentum signal turns non-zero and the 'adx' filter allows it; orders go in at the NEXT bar's open (never the signal bar's close) | M25: exit after 20 bars, or on a 2-ATR stop | N25: stop at 2 ATR from entry | O25: max_bars=20, stop_atr=2.0 | P25: Stocks only: no change (stop 2 ATR). | Q25: n/a (stocks)
... A49: 1 CORE | C49: vol_breakout.trend200.time | D49: Breakout when volatility expands | E49: C | F49: C | G49: Futures, daily bars (Larry Williams, industry) | H49: Daily-bar idea. Intraday use is unproven. Old bots using it averaged test Sharpe -4.2 (tiny samples). | I49: medium (hard stop) | J49: 5m, 15m, 30m, 1h, 4h, 1d | K49: crypto, stock, etf, fx, future | L49: vol_breakout signal turns non-zero and the 'trend200' filter allows it; orders go in at the NEXT bar's open (never the signal bar's close) | M49: exit after 20 bars, or on a 2-ATR stop | N49: stop at 2 ATR from entry | O49: k=0.6, max_bars=20, stop_atr=2.0 | P49: Crypto: stop 3-4 ATR (not 2), 0.6x size when volatility is LOUD, skip when QUIET, no Sat/Sun entries, skip if cost > 20% of 1R (20-33% = half size). | Q49: Not tested in your BTC study.
A50: 2 TEST | B50: Yes | C50: bollinger_reversion.vol_band.atr_bracket | D50: Fade a move outside Bollinger bands | E50: D | F50: D | G50: No independent test (trader idea) | H50: Needs independent testing before any trust. | I50: medium (hard stop) | J50: 5m, 15m, 30m, 1h, 4h, 1d | K50: crypto, stock, etf, fx, future | L50: bollinger_reversion signal turns non-zero and the 'vol_band' filter allows it; orders go in at the NEXT bar's open (never the signal bar's close) | M50: stop 2 ATR, target 2R (4 ATR), whichever comes first; signal flip also exits | N50: stop at 2 ATR from entry | O50: n=20, k=2.0, stop_atr=2.0, target_r=2.0 | P50: Crypto: stop 3-4 ATR (not 2), 0.6x size when volatility is LOUD, skip when QUIET, no Sat/Sun entries, skip if cost > 20% of 1R (20-33% = half size). | Q50: Not tested in your BTC study.
A51: 2 TEST | B51: Yes | C51: initial_balance_breakout.relvol.atr_bracket | D51: Stocks: break of the first-hour high/low | E51: D | F51: D | G51: No independent test (trader idea) | H51: Needs independent testing before any trust. | I51: medium (hard stop) | J51: 5m, 15m | K51: stock, etf, future | L51: initial_balance_breakout signal turns non-zero and the 'relvol' filter allows it; orders go in at the NEXT bar's open (never the signal bar's close) | M51: stop 2 ATR, target 2R (4 ATR), whichever comes first; signal flip also exits | N51: stop at 2 ATR from entry | O51: stop_atr=2.0, target_r=2.0 | P51: Stocks only: no change (stop 2 ATR). | Q51: n/a (stocks)
A52: 2 TEST | B52: Yes | C52: squeeze_breakout.adx.trail | D52: Breakout after a volatility squeeze | E52: D | F52: D | G52: No independent test (trader idea) | H52: Needs independent testing before any trust. | I52: medium (hard stop) | J52: 5m, 15m, 30m, 1h, 4h, 1d | K52: crypto, stock, etf, fx, future | L52: squeeze_breakout signal turns non-zero and the 'adx' filter allows it; orders go in at the NEXT bar's open (never the signal bar's close) | M52: 3-ATR trailing stop; signal flip also exits | N52: 3-ATR trailing stop | O52: p=10, trail_atr=3.0 | P52: Crypto: stop 3-4 ATR (not 2), 0.6x size when volatility is LOUD, skip when QUIET, no Sat/Sun entries, skip if cost > 20% of 1R (20-33% = half size). | Q52: Not tested in your BTC study.
A53: 2 TEST | B53: Yes | C53: zscore_reversion.none.atr_bracket | D53: Buy when price is far below its average (only family with watch-list bots) | E53: D | F53: D | G53: No independent test (trader idea) | H53: Needs independent testing before any trust. | I53: medium (hard stop) | J53: 5m, 15m, 30m, 1h, 4h, 1d | K53: crypto, stock, etf, fx, future | L53: zscore_reversion signal turns non-zero and the 'none' filter allows it; orders go in at the NEXT bar's open (never the signal bar's close) | M53: stop 2 ATR, target 2R (4 ATR), whichever comes first; signal flip also exits | N53: stop at 2 ATR from entry | O53: n=50, z=2.0, stop_atr=2.0, target_r=2.0 | P53: Crypto: stop 3-4 ATR (not 2), 0.6x size when volatility is LOUD, skip when QUIET, no Sat/Sun entries, skip if cost > 20% of 1R (20-33% = half size). | Q53: Not tested in your BTC study.
A54: 2 TEST | C54: bollinger_reversion.none.atr_bracket | D54: Fade a move outside Bollinger bands | E54: D | F54: D | G54: No independent test (trader idea) | H54: Needs independent testing before any trust. | I54: medium (hard stop) | J54: 5m, 15m, 30m, 1h, 4h, 1d | K54: crypto, stock, etf, fx, future | L54: bollinger_reversion signal turns non-zero and the 'none' filter allows it; orders go in at the NEXT bar's open (never the signal bar's close) | M54: stop 2 ATR, target 2R (4 ATR), whichever comes first; signal flip also exits | N54: stop at 2 ATR from entry | O54: n=20, k=2.0, stop_atr=2.0, target_r=2.0 | P54: Crypto: stop 3-4 ATR (not 2), 0.6x size when volatility is LOUD, skip when QUIET, no Sat/Sun entries, skip if cost > 20% of 1R (20-33% = half size). | Q54: Not tested in your BTC study.
A55: 2 TEST | C55: bollinger_reversion.none.time | D55: Fade a move outside Bollinger bands | E55: D | F55: D | G55: No independent test (trader idea) | H55: Needs independent testing before any trust. | I55: medium (hard stop) | J55: 5m, 15m, 30m, 1h, 4h, 1d | K55: crypto, stock, etf, fx, future | L55: bollinger_reversion signal turns non-zero and the 'none' filter allows it; orders go in at the NEXT bar's open (never the signal bar's close) | M55: exit after 20 bars, or on a 2-ATR stop | N55: stop at 2 ATR from entry | O55: n=20, k=2.0, max_bars=20, stop_atr=2.0 | P55: Crypto: stop 3-4 ATR (not 2), 0.6x size when volatility is LOUD, skip when QUIET, no Sat/Sun entries, skip if cost > 20% of 1R (20-33% = half size). | Q55: Not tested in your BTC study.
A56: 2 TEST | C56: bollinger_reversion.vol_band.time | D56: Fade a move outside Bollinger bands | E56: D | F56: D | G56: No independent test (trader idea) | H56: Needs independent testing before any trust. | I56: medium (hard stop) | J56: 5m, 15m, 30m, 1h, 4h, 1d | K56: crypto, stock, etf, fx, future | L56: bollinger_reversion signal turns non-zero and the 'vol_band' filter allows it; orders go in at the NEXT bar's open (never the signal bar's close) | M56: exit after 20 bars, or on a 2-ATR stop | N56: stop at 2 ATR from entry | O56: n=20, k=2.0, max_bars=20, stop_atr=2.0 | P56: Crypto: stop 3-4 ATR (not 2), 0.6x size when volatility is LOUD, skip when QUIET, no Sat/Sun entries, skip if cost > 20% of 1R (20-33% = half size). | Q56: Not tested in your BTC study.
A57: 2 TEST | C57: crypto_weekend.none.time | D57: Crypto: weekend pattern (1h/4h only) | E57: D | F57: D | G57: No independent test (trader idea) | H57: Needs independent testing before any trust. | I57: medium (hard stop) | J57: 1h, 4h | K57: crypto | L57: crypto_weekend signal turns non-zero and the 'none' filter allows it; orders go in at the NEXT bar's open (never the signal bar's close) | M57: exit after 20 bars, or on a 2-ATR stop | N57: stop at 2 ATR from entry | O57: max_bars=20, stop_atr=2.0 | P57: Crypto: stop 3-4 ATR (not 2), 0.6x size when volatility is LOUD, skip when QUIET, no Sat/Sun entries, skip if cost > 20% of 1R (20-33% = half size). | Q57: Not tested in your BTC study.
A58: 2 TEST | C58: failed_breakout.none.atr_bracket | D58: Fade a breakout that fails and snaps back | E58: D | F58: D | G58: No independent test (trader idea) | H58: Needs independent testing before any trust. | I58: medium (hard stop) | J58: 5m, 15m, 30m, 1h, 4h, 1d | K58: crypto, stock, etf, fx, future | L58: failed_breakout signal turns non-zero and the 'none' filter allows it; orders go in at the NEXT bar's open (never the signal bar's close) | M58: stop 2 ATR, target 2R (4 ATR), whichever comes first; signal flip also exits | N58: stop at 2 ATR from entry | O58: n=20, m=3, stop_atr=2.0, target_r=2.0 | P58: Crypto: stop 3-4 ATR (not 2), 0.6x size when volatility is LOUD, skip when QUIET, no Sat/Sun entries, skip if cost > 20% of 1R (20-33% = half size). | Q58: Not tested in your BTC study.
A59: 2 TEST | C59: failed_breakout.none.time | D59: Fade a breakout that fails and snaps back | E59: D | F59: D | G59: No independent test (trader idea) | H59: Needs independent testing before any trust. | I59: medium (hard stop) | J59: 5m, 15m, 30m, 1h, 4h, 1d | K59: crypto, stock, etf, fx, future | L59: failed_breakout signal turns non-zero and the 'none' filter allows it; orders go in at the NEXT bar's open (never the signal bar's close) | M59: exit after 20 bars, or on a 2-ATR stop | N59: stop at 2 ATR from entry | O59: n=20, m=3, max_bars=20, stop_atr=2.0 | P59: Crypto: stop 3-4 ATR (not 2), 0.6x size when volatility is LOUD, skip when QUIET, no Sat/Sun entries, skip if cost > 20% of 1R (20-33% = half size). | Q59: Not tested in your BTC study.
A60: 2 TEST | C60: failed_breakout.vol_band.atr_bracket | D60: Fade a breakout that fails and snaps back | E60: D | F60: D | G60: No independent test (trader idea) | H60: Needs independent testing before any trust. | I60: medium (hard stop) | J60: 5m, 15m, 30m, 1h, 4h, 1d | K60: crypto, stock, etf, fx, future | L60: failed_breakout signal turns non-zero and the 'vol_band' filter allows it; orders go in at the NEXT bar's open (never the signal bar's close) | M60: stop 2 ATR, target 2R (4 ATR), whichever comes first; signal flip also exits | N60: stop at 2 ATR from entry | O60: n=20, m=3, stop_atr=2.0, target_r=2.0 | P60: Crypto: stop 3-4 ATR (not 2), 0.6x size when volatility is LOUD, skip when QUIET, no Sat/Sun entries, skip if cost > 20% of 1R (20-33% = half size). | Q60: Not tested in your BTC study.
A61: 2 TEST | C61: failed_breakout.vol_band.time | D61: Fade a breakout that fails and snaps back | E61: D | F61: D | G61: No independent test (trader idea) | H61: Needs independent testing before any trust. | I61: medium (hard stop) | J61: 5m, 15m, 30m, 1h, 4h, 1d | K61: crypto, stock, etf, fx, future | L61: failed_breakout signal turns non-zero and the 'vol_band' filter allows it; orders go in at the NEXT bar's open (never the signal bar's close) | M61: exit after 20 bars, or on a 2-ATR stop | N61: stop at 2 ATR from entry | O61: n=20, m=3, max_bars=20, stop_atr=2.0 | P61: Crypto: stop 3-4 ATR (not 2), 0.6x size when volatility is LOUD, skip when QUIET, no Sat/Sun entries, skip if cost > 20% of 1R (20-33% = half size). | Q61: Not tested in your BTC study.
A62: 2 TEST | C62: gap_continuation.none.atr_bracket | D62: Follow an opening gap that holds | E62: D | F62: D | G62: No independent test (trader idea) | H62: Needs independent testing before any trust. | I62: medium (hard stop) | J62: 1m, 5m, 15m, 30m, 1h | K62: stock, etf, future | L62: gap_continuation signal turns non-zero and the 'none' filter allows it; orders go in at the NEXT bar's open (never the signal bar's close) | M62: stop 2 ATR, target 2R (4 ATR), whichever comes first; signal flip also exits | N62: stop at 2 ATR from entry | O62: g=0.005, stop_atr=2.0, target_r=2.0 | P62: Stocks only: no change (stop 2 ATR). | Q62: n/a (stocks)
A63: 2 TEST | C63: gap_continuation.none.time | D63: Follow an opening gap that holds | E63: D | F63: D | G63: No independent test (trader idea) | H63: Needs independent testing before any trust. | I63: medium (hard stop) | J63: 1m, 5m, 15m, 30m, 1h | K63: stock, etf, future | L63: gap_continuation signal turns non-zero and the 'none' filter allows it; orders go in at the NEXT bar's open (never the signal bar's close) | M63: exit after 20 bars, or on a 2-ATR stop | N63: stop at 2 ATR from entry | O63: g=0.005, max_bars=20, stop_atr=2.0 | P63: Stocks only: no change (stop 2 ATR). | Q63: n/a (stocks)
...

Sheet New (to build)
A1: ID | B1: Family | C1: Job | D1: Evidence | E1: Research card | F1: Plain rules (to build) | G1: Bars | H1: Status
A2: vwap_reversion.vol_band.time | B2: mean_reversion | C2: Fade a stretch away from VWAP (day average price) back to it | D2: H | E2: ST024 | F2: Buy when price is far below VWAP and the day is calm; sell back at VWAP. Exit after 20 bars or 2-ATR stop. | G2: 5m, 15m | H2: NEW - not built yet. Build, then test like every other strategy. Never trade untested.
A3: vwap_reversion.none.atr_bracket | B3: mean_reversion | C3: Same, plain version (control) | D3: H | E3: ST024 | F3: Same entry; stop 2 ATR, target 2R. | G3: 5m, 15m | H3: NEW - not built yet. Build, then test like every other strategy. Never trade untested.
A4: vwap_trend_pullback.adx.atr_bracket | B4: trend | C4: Buy a dip to VWAP inside a strong up-trend | D4: H | E4: ST023 | F4: Trend is up (ADX strong), price pulls back to VWAP and turns up. Stop 2 ATR, target 2R. | G4: 5m, 15m | H4: NEW - not built yet. Build, then test like every other strategy. Never trade untested.
A5: vwap_trend_pullback.trend200.trail | B5: trend | C5: Same, with a trailing stop | D5: H | E5: ST023 | F5: Same entry; 3-ATR trailing stop, flat before close. | G5: 5m, 15m | H5: NEW - not built yet. Build, then test like every other strategy. Never trade untested.
A6: orb.stocks_in_play.eod_or_atr_stop | B6: breakout | C6: Stocks: 5-15 min opening-range breakout, only the top ~20 stocks by opening relative volume (>=100% RVOL, ATR above ~1% of price) | D6: C | E6: ST122 | F6: Rank stocks at 9:35 ET by opening volume vs the 14-day norm. Keep the top 20 with a catalyst. Long if the first candle closed up. Stop at the other side of the range or a fraction of ATR. Exit by the close. Needs minute data and a universe of thousands of stocks, so it runs as ONE pooled strategy, not one bot per stock. Paper: Sharpe 2.81; independent QuantConnect rebuild 2.40. Authors sell trading education, so treat as an upper bound. | G6: 1m-5m | H6: NEW - not built yet. Build, then test like every other strategy. Never trade untested.
A7: vol_gate.overlay | B7: overlay | C7: Volatility gate for everything: trade only when the next 12-24h is forecast LOUD or NORMAL, stand down when QUIET | D7: C | E7: own BTC study | F7: Forecast volatility (not direction). Your own 67,585-bar BTC test: volatility AUC 0.72-0.75, direction AUC 0.513. In that test the gate cut max drawdown from -20.0% to -11.7%. Use LOUD = wider stop, 0.6x size. | G7: 1h | H7: NEW - not built yet. Build, then test like every other strategy. Never trade untested.
A8: btc_led_alt_trend.trend_confirm.trail | B8: trend | C8: Crypto alts: only go long an alt while BTC trend filter is ON | D8: D | E8: practitioner | F8: Alts behave like leveraged BTC. Skip alt longs when BTC is below its trend line. | G8: 1h-4h | H8: NEW - not built yet. Build, then test like every other strategy. Never trade untested.
A9: attention_momentum.liquidity_gate.time_stop | B9: momentum | C9: CEX-listed meme coins: tiny fixed-risk entry on a volume/attention spike while BTC trend is ON; hard 24-72h time stop | D9: D | E9: no robust evidence | F9: Unproven. Assume it fails until the gate says otherwise. Meme sleeve only, max 5% of paper capital. | G9: 1h | H9: NEW - not built yet. Build, then test like every other strategy. Never trade untested.
A10: vol_gate_swing.btc.long_only | B10: swing (not a day trade) | C10: BTC then ETH, SOL: long only, only when the volatility gate reads LOUD or NORMAL, wide stop, 96-hour limit | D10: C | E10: own BTC study | F10: Long only. Skip QUIET. Stop 4 ATR, target 2R, time limit 96 hours. Limit orders where possible. No Sat/Sun entries. Your measured result: 224 trades in 7.7 years, 48.7% hit, +0.125R per trade, profit factor 1.27, max drawdown -11.7%. Caveats: one asset; it was the best of 72 configurations tried, so it is probably flattered; 19 of the 21 positive configs needed maker-tier fees; it is a swing trade, so it breaks the 'flat in 12 hours' rule. Test it as a hypothesis through the full gate. Also test 12h and 24h hold limits to see if a day-trade version survives. | G10: 1h | H10: NEW - not built yet. Build, then test like every other strategy. Never trade untested.
A11: crypto_session_orb.vol_gate.wide_stop | B11: breakout | C11: BTC/ETH/SOL: opening-range breakout at the US stock open (7:30 am MT), volatility-gated, wide stop | D11: C | E11: own BTC study | F11: Opening range = first 15 min after 7:30 am MT. Long if a 5m bar closes above the range with RVOL over 1.5 and the 1h trend agrees. Stop 4 ATR (not the other side of the range, unless that is far enough away to pass the cost rule). Target 2R. Skip if the range is over 1.5 ATR or tier-1 news is due. Your measured result: 590 trades, 42.7% hit, +0.130R before costs, +0.015R after 30bp - about break-even. At a 1 ATR stop it lost money (-0.039R before costs). | G11: 5m, 1h | H11: NEW - not built yet. Build, then test like every other strategy. Never trade untested.
A12: maker_limit_entry.overlay | B12: execution overlay | C12: Use limit (maker) orders instead of market orders wherever the setup allows waiting | D12: C | E12: own BTC study | F12: Not a signal. An execution rule. At Kraken Pro a taker round trip is 0.52% and a maker round trip 0.32%; at NDAX the fee is flat 0.20% each way, so there is no maker saving there. Model fills honestly: a limit order can miss the trade, and the missed trades are often the winners. Test with a fill-probability model, not 100% fills. | G12: any | H12: NEW - not built yet. Build, then test like every other strategy. Never trade untested.

Sheet Do not build
A1: Idea | B1: Why not
A2: Martingale / averaging down | B2: One long trend wipes the account.
A3: Grid bots without a stop | B3: Profit in ranges, then hold the full bag in a breakdown. Worst on meme coins.
A4: Indicator-only crossover bots (RSI/MACD alone) | B4: Your own 72-configuration study and 0/100 gate result: they do not survive costs.
A5: High-leverage scalping / perpetual futures | B5: Barred for Canadian retail; tiny R means fees dominate.
A6: Copy-trading, signal groups, AI "agent" tokens | B6: No verifiable track record. Malware was sold disguised as crypto trading bots.
A7: New on-chain meme launches (pump.fun style) | B7: Research found most such tokens show rug-pull traits within an hour; 98.6% of pump.fun tokens collapsed (Solidus Labs 2025).
A8: Short signals and flip exits | B8: Long only, hard stop on every trade.
A9: Tight-stop crypto scalping/day trading at retail spot fees (1-2 ATR stops) | B9: Your study: cost is 0.48-0.75R per trade at Kraken/NDAX fees. 0 of 72 configurations made money at taker fees.
A10: VWAP 2-sigma fade on BTC | B10: Your study: only 30 fires in 7.7 years and negative expectancy (-0.06R before costs). (The VWAP reclaim and the other VWAP variants stay in 'New'.)
A11: Hour-of-day entry rules (for example 'long BTC at 22:00 UTC') | B11: A published claim of 33%/year (Sharpe 1.58) measured +1.6%/year, Sharpe 0.09, before fees on 2019-2026, and negative after every fee tier. With 24 hours tested, you need t of about 2.9 to beat chance.
A12: New crypto-major entries on Saturday/Sunday | B12: Your study: weekend direction AUC 0.498 on 16,224 bars = no edge. Rule, not preference.
A13: Trusting a quoted win rate without its exit rule | B13: Quotes like 'RSI-2 wins 72-74%' or 'ORB 52-58%' assume a different exit than a fixed 2R target. At a fixed-R exit both sit near 43-45%.

Sheet Cut
A1: Generator | B1: Family | C1: Evidence | D1: Variants in export | E1: Reason
A2: adx_di | B2: trend | C2: D | D2: 20 | E2: CUT - copy of a stronger idea, no evidence (grade D)
A3: ao_zero | B3: momentum | C3: D | D3: 24 | E3: CUT - copy of a stronger idea, no evidence (grade D)
A4: aroon_trend | B4: trend | C4: D | D4: 24 | E4: CUT - copy of a stronger idea, no evidence (grade D)
A5: atr_channel_breakout | B5: breakout | C5: D | D5: 15 | E5: CUT - copy of a stronger idea, no evidence (grade D)
A6: autocorr_follow | B6: statistical | C6: D | D6: 12 | E6: CUT - copy of a stronger idea, no evidence (grade D)
A7: cci_reversion | B7: mean_reversion | C7: D | D7: 24 | E7: CUT - copy of a stronger idea, no evidence (grade D)
A8: cmo_momentum | B8: momentum | C8: D | D8: 24 | E8: CUT - copy of a stronger idea, no evidence (grade D)
A9: consolidation_breakout | B9: breakout | C9: D | D9: 10 | E9: CUT - copy of a stronger idea, no evidence (grade D)
A10: coppock_turn | B10: momentum | C10: D | D10: 18 | E10: CUT - copy of a stronger idea, no evidence (grade D)
A11: donchian_breakout | B11: breakout | C11: D | D11: 18 | E11: CUT - copy of a stronger idea, no evidence (grade D)
A12: elder_impulse | B12: momentum | C12: D | D12: 24 | E12: CUT - copy of a stronger idea, no evidence (grade D)
A13: ema_cross | B13: trend | C13: D | D13: 20 | E13: CUT - copy of a stronger idea, no evidence (grade D)
... A57: absorption | B57: microstructure | C57: D | D57: 1 | E57: CUT - needs data we do not have (trades, order_book)

Sheet Day-trade rules
A1: Market | B1: Bar size | C1: Must be flat | D1: Max bars per trade | E1: Notes
A2: US stocks | B2: 5m / 15m | C2: Flat by 3:55 pm ET (1:55 pm MT) | D2: 20 bars | E2: New entries 9:35 am-3:30 pm ET (7:35 am-1:30 pm MT). Exception: first_hour_momentum enters at 3:30 pm ET. Use an exchange calendar: early-close days end at 1 pm ET.
A3: US stocks | B3: 1h | C3: Flat by 3:55 pm ET (1:55 pm MT) | D3: 5 bars | E3: The default 20-bar exit would hold about 3 days. Override it. Enter by 2:30 pm ET.
A4: Crypto | B4: 1h | C4: 12 hours after entry | D4: 12 bars | E4: Long only. Max 2 crypto trades open at once (coins move together). v5: stop 3-4 ATR, no Sat/Sun entries, skip QUIET. NOTE: the structure that worked in your BTC study held trades up to 96 hours. A 12-hour version at wide stops is UNTESTED, so test it before trusting it.
A5: Stocks | B5: any | C5: Hard stop 2 ATR on every trade | D5: - | E5: No flip exits. Never widen a stop. Never add to a loser. Stocks: 2 ATR stop is fine because stock costs are small compared with the stop.
A6: All | B6: any | C6: Long only | D6: - | E6: Short signals are ignored (WAIT). Train and gate bots long-only so the test matches what is traded.
A7: All | B7: any | C7: Signal on bar close, trade on the NEXT bar | D7: - | E7: Never fill at the same bar that made the signal. Same-bar fills are a common way backtests lie.
A8: All | B8: any | C8: Costs on, and a cost check | D8: - | E8: Charge spread + fees + slippage on every test trade. Cost in R = round-trip cost / stop distance. Up to 20% of 1R = fine. 20-33% = half size, paper only. Over 33% = WAIT. Also profit at 2x costs.
A9: Crypto | B9: 1h | C9: Swing option: up to 96 hours | D9: 96 bars | E9: Paper-test only as a separate 'swing' mode (strategy vol_gate_swing.btc.long_only). It is not a day trade, and it must pass the same gate.
A10: Crypto | B10: any | C10: Hard stop 3-4 ATR on every trade | D10: - | E10: Never 1-2 ATR at NDAX/Kraken fees (cost 0.3-0.75R). Smaller size instead of a tighter stop.
A11: Crypto | B11: any | C11: No new entries Sat/Sun | D11: - | E11: Measured no-edge on weekends (BTC). Applies to majors; apply to the rest until tested.

Sheet Cost in R
A1: Cost in R = round-trip cost % / stop %. Change the yellow cells. Green = 0.20R or less (fine). Amber = 0.20-0.33R (half size). Red = over 0.33R (WAIT).
A3: Typical hourly ATR % of price
A4: BTC (median in your study) | B4: 0.69 | C4: % of price
A5: US large-cap stock (ASSUMPTION - replace with real) | B5: 0.5 | C5: % of price
A7: Venue (round-trip cost, % of trade) | B7: Cost % | C7: 1 ATR stop | D7: 1.5 ATR stop | E7: 2 ATR stop | F7: 3 ATR stop | G7: 4 ATR stop | H7: Smallest stop (in ATR) that keeps cost at 20% of 1R
A8: Crypto: Kraken Pro taker (0.26% each way) | B8: 0.52 | C8: =$B8/($B$4*1) -> 0.75362319 | D8: =$B8/($B$4*1.5) -> 0.50241546 | E8: =$B8/($B$4*2) -> 0.37681159 | F8: =$B8/($B$4*3) -> 0.25120773 | G8: =$B8/($B$4*4) -> 0.1884058 | H8: =$B8/(0.2*$B$4) -> 3.7681159
A9: Crypto: NDAX (flat 0.20% each way) | B9: 0.4 | C9: =$B9/($B$4*1) -> 0.57971014 | D9: =$B9/($B$4*1.5) -> 0.38647343 | E9: =$B9/($B$4*2) -> 0.28985507 | F9: =$B9/($B$4*3) -> 0.19323671 | G9: =$B9/($B$4*4) -> 0.14492754 | H9: =$B9/(0.2*$B$4) -> 2.8985507
A10: Crypto: Kraken Pro maker (0.16% each way) | B10: 0.32 | C10: =$B10/($B$4*1) -> 0.46376812 | D10: =$B10/($B$4*1.5) -> 0.30917874 | E10: =$B10/($B$4*2) -> 0.23188406 | F10: =$B10/($B$4*3) -> 0.15458937 | G10: =$B10/($B$4*4) -> 0.11594203 | H10: =$B10/(0.2*$B$4) -> 2.3188406
A11: Crypto: ~10 bp maker tier (best case) | B11: 0.1 | C11: =$B11/($B$4*1) -> 0.14492754 | D11: =$B11/($B$4*1.5) -> 0.096618357 | E11: =$B11/($B$4*2) -> 0.072463768 | F11: =$B11/($B$4*3) -> 0.048309179 | G11: =$B11/($B$4*4) -> 0.036231884 | H11: =$B11/(0.2*$B$4) -> 0.72463768
A12: US stock (ASSUMPTION: spread + fees) | B12: 0.06 | C12: =$B12/($B$5*1) -> 0.12 | D12: =$B12/($B$5*1.5) -> 0.08 | E12: =$B12/($B$5*2) -> 0.06 | F12: =$B12/($B$5*3) -> 0.04 | G12: =$B12/($B$5*4) -> 0.03 | H12: =$B12/(0.2*$B$5) -> 0.6
A14: Fees move. Kraken's July 2026 numbers conflicted between sources in my research; use YOUR account's real tier. Stock cost is my placeholder, not a measured number.

Sheet Measured (BTC)
A1: Topic | B1: Result | C1: Data / note
A2: Direction vs volatility | B2: Direction AUC 0.513 (0.500 = coin flip). Volatility AUC 0.716 (LOUD) and 0.747 (QUIET). When the volatility model is confident it is 82-85% right, on about 2-5% of bars. | C2: 67,585 hourly bars, 2019-2026, walk-forward
A3: Leakage control | B3: Real labels AUC 0.521; shuffled labels 0.499. The small edge is real but small. | C3: same
A4: Weekend | B4: Direction AUC 0.498 on 16,224 weekend bars: no edge. | C4: same
A5: Configurations tested | B5: 72. Zero profitable at retail taker fees. 19 of the 21 positive results needed maker-tier fees. | C5: same
A6: Best structure | B6: Stop 4 ATR, target 2R, 96-hour limit, long only, volatility gate: 224 trades, 48.7% hit, +0.125R, profit factor 1.27, max drawdown -11.7%. Gate lowered drawdown from -20.0% to -11.7%. | C6: same
A7: TIGHT structure (stop 1 ATR, target 1.5R, 24h) - setup | trades | gross hit | gross R | net R @30bp | cost R | B7: RSI-2 | 1361 | 43.3% | +0.076 | -0.406 | 0.48 ; Sweep reclaim | 953 | 40.9% | +0.017 | -0.448 | 0.47 ; Trend pullback | 1296 | 40.7% | +0.008 | -0.476 | 0.48 ; Breakout retest | 761 | 40.2% | +0.007 | -0.466 | 0.47 ; Every bar (benchmark) | 10900 | 40.1% | -0.005 | -0.481 | 0.48 ; ORB | 967 | 38.7% | -0.039 | -0.520 | 0.48 | C7: same
A8: WIDE structure (stop 4 ATR, target 2R, 96h) - same columns | B8: ORB | 590 | 42.7% | +0.130 | +0.015 | 0.12 ; RSI-2 | 492 | 44.9% | +0.113 | -0.003 | 0.12 ; Breakout retest | 428 | 42.3% | +0.110 | -0.007 | 0.12 ; Trend pullback | 476 | 43.5% | +0.093 | -0.026 | 0.12 ; Every bar (benchmark) | 1236 | 44.0% | +0.085 | -0.026 | 0.11 ; Sweep reclaim | 561 | 43.5% | +0.058 | -0.057 | 0.12 ; VWAP 2-sigma fade | 30 | 40.0% | -0.060 | -0.173 | 0.11 | C8: same
A9: Lesson | B9: Most setups barely beat 'just be long every bar'. Always compare to the benchmark. The same setups flip from worst to best only by stop width and hold time. | C9: same
A10: How far to trust this | B10: Source: your Jarvus skill (v5 science notes). I read the numbers there and copied them. I did not re-run them. BTC only, hourly bars, one asset class. Winners picked from 72 tries are flattered. Stocks and other coins are untested. | C10: -
